2019-08-07 17:59:10,088 WARNING MESSAGE: Not Found: /
2019-08-07 17:59:19,184 WARNING MESSAGE: Not Found: /favicon.ico
2019-08-07 17:59:22,617 WARNING MESSAGE: Not Found: /home/#.png
2019-08-07 18:08:21,084 WARNING MESSAGE: Not Found: /search_ans/style.css
2019-08-07 18:08:21,095 WARNING MESSAGE: Not Found: /search_ans/temp.png
2019-08-07 18:17:14,135 WARNING MESSAGE: Not Found: /home/#.png
2019-08-07 18:17:21,669 WARNING MESSAGE: Not Found: /home/#.png
2019-08-07 18:18:28,237 ERROR MESSAGE: Internal Server Error: /search_result/
Traceback (most recent call last):
  File "C:\Users\SUNNY\workspace\XYZPro\fda\lib\site-packages\django\core\handlers\exception.py", line 35, in inner
    response = get_response(request)
  File "C:\Users\SUNNY\workspace\XYZPro\fda\lib\site-packages\django\core\handlers\base.py", line 128, in _get_response
    response = self.process_exception_by_middleware(e, request)
  File "C:\Users\SUNNY\workspace\XYZPro\fda\lib\site-packages\django\core\handlers\base.py", line 126, in _get_response
    response = wrapped_callback(request, *callback_args, **callback_kwargs)
  File "C:\Users\SUNNY\workspace\XYZPro\fda\lib\site-packages\django\contrib\auth\decorators.py", line 21, in _wrapped_view
    return view_func(request, *args, **kwargs)
  File "C:\Users\SUNNY\workspace\XYZPro\fda\lib\site-packages\django\views\generic\base.py", line 69, in view
    return self.dispatch(request, *args, **kwargs)
  File "C:\Users\SUNNY\workspace\XYZPro\fda\lib\site-packages\django\views\generic\base.py", line 89, in dispatch
    return handler(request, *args, **kwargs)
  File "C:\Users\SUNNY\workspace\XYZPro\fda\lib\site-packages\django\views\generic\list.py", line 142, in get
    self.object_list = self.get_queryset()
  File "C:\Users\SUNNY\workspace\XYZPro\XYZFDA\account\views.py", line 168, in get_queryset
    Q(name__startswith=query) & Q(date__gte=query2, date__lt=query5))
  File "C:\Users\SUNNY\workspace\XYZPro\fda\lib\site-packages\django\db\models\manager.py", line 82, in manager_method
    return getattr(self.get_queryset(), name)(*args, **kwargs)
  File "C:\Users\SUNNY\workspace\XYZPro\fda\lib\site-packages\django\db\models\query.py", line 836, in filter
    return self._filter_or_exclude(False, *args, **kwargs)
  File "C:\Users\SUNNY\workspace\XYZPro\fda\lib\site-packages\django\db\models\query.py", line 854, in _filter_or_exclude
    clone.query.add_q(Q(*args, **kwargs))
  File "C:\Users\SUNNY\workspace\XYZPro\fda\lib\site-packages\django\db\models\sql\query.py", line 1253, in add_q
    clause, _ = self._add_q(q_object, self.used_aliases)
  File "C:\Users\SUNNY\workspace\XYZPro\fda\lib\site-packages\django\db\models\sql\query.py", line 1271, in _add_q
    current_negated, allow_joins, split_subq)
  File "C:\Users\SUNNY\workspace\XYZPro\fda\lib\site-packages\django\db\models\sql\query.py", line 1277, in _add_q
    split_subq=split_subq,
  File "C:\Users\SUNNY\workspace\XYZPro\fda\lib\site-packages\django\db\models\sql\query.py", line 1215, in build_filter
    condition = self.build_lookup(lookups, col, value)
  File "C:\Users\SUNNY\workspace\XYZPro\fda\lib\site-packages\django\db\models\sql\query.py", line 1090, in build_lookup
    raise ValueError("Cannot use None as a query value")
ValueError: Cannot use None as a query value
2019-08-07 18:19:01,447 ERROR MESSAGE: Internal Server Error: /search_result/
Traceback (most recent call last):
  File "C:\Users\SUNNY\workspace\XYZPro\fda\lib\site-packages\django\core\handlers\exception.py", line 35, in inner
    response = get_response(request)
  File "C:\Users\SUNNY\workspace\XYZPro\fda\lib\site-packages\django\core\handlers\base.py", line 128, in _get_response
    response = self.process_exception_by_middleware(e, request)
  File "C:\Users\SUNNY\workspace\XYZPro\fda\lib\site-packages\django\core\handlers\base.py", line 126, in _get_response
    response = wrapped_callback(request, *callback_args, **callback_kwargs)
  File "C:\Users\SUNNY\workspace\XYZPro\fda\lib\site-packages\django\contrib\auth\decorators.py", line 21, in _wrapped_view
    return view_func(request, *args, **kwargs)
  File "C:\Users\SUNNY\workspace\XYZPro\fda\lib\site-packages\django\views\generic\base.py", line 69, in view
    return self.dispatch(request, *args, **kwargs)
  File "C:\Users\SUNNY\workspace\XYZPro\fda\lib\site-packages\django\views\generic\base.py", line 89, in dispatch
    return handler(request, *args, **kwargs)
  File "C:\Users\SUNNY\workspace\XYZPro\fda\lib\site-packages\django\views\generic\list.py", line 142, in get
    self.object_list = self.get_queryset()
  File "C:\Users\SUNNY\workspace\XYZPro\XYZFDA\account\views.py", line 168, in get_queryset
    Q(name__startswith=query) & Q(date__gte=query2, date__lt=query5))
  File "C:\Users\SUNNY\workspace\XYZPro\fda\lib\site-packages\django\db\models\manager.py", line 82, in manager_method
    return getattr(self.get_queryset(), name)(*args, **kwargs)
  File "C:\Users\SUNNY\workspace\XYZPro\fda\lib\site-packages\django\db\models\query.py", line 836, in filter
    return self._filter_or_exclude(False, *args, **kwargs)
  File "C:\Users\SUNNY\workspace\XYZPro\fda\lib\site-packages\django\db\models\query.py", line 854, in _filter_or_exclude
    clone.query.add_q(Q(*args, **kwargs))
  File "C:\Users\SUNNY\workspace\XYZPro\fda\lib\site-packages\django\db\models\sql\query.py", line 1253, in add_q
    clause, _ = self._add_q(q_object, self.used_aliases)
  File "C:\Users\SUNNY\workspace\XYZPro\fda\lib\site-packages\django\db\models\sql\query.py", line 1271, in _add_q
    current_negated, allow_joins, split_subq)
  File "C:\Users\SUNNY\workspace\XYZPro\fda\lib\site-packages\django\db\models\sql\query.py", line 1277, in _add_q
    split_subq=split_subq,
  File "C:\Users\SUNNY\workspace\XYZPro\fda\lib\site-packages\django\db\models\sql\query.py", line 1215, in build_filter
    condition = self.build_lookup(lookups, col, value)
  File "C:\Users\SUNNY\workspace\XYZPro\fda\lib\site-packages\django\db\models\sql\query.py", line 1090, in build_lookup
    raise ValueError("Cannot use None as a query value")
ValueError: Cannot use None as a query value
2019-08-07 18:19:46,278 ERROR MESSAGE: Internal Server Error: /search_result/
Traceback (most recent call last):
  File "C:\Users\SUNNY\workspace\XYZPro\fda\lib\site-packages\django\core\handlers\exception.py", line 35, in inner
    response = get_response(request)
  File "C:\Users\SUNNY\workspace\XYZPro\fda\lib\site-packages\django\core\handlers\base.py", line 128, in _get_response
    response = self.process_exception_by_middleware(e, request)
  File "C:\Users\SUNNY\workspace\XYZPro\fda\lib\site-packages\django\core\handlers\base.py", line 126, in _get_response
    response = wrapped_callback(request, *callback_args, **callback_kwargs)
  File "C:\Users\SUNNY\workspace\XYZPro\fda\lib\site-packages\django\contrib\auth\decorators.py", line 21, in _wrapped_view
    return view_func(request, *args, **kwargs)
  File "C:\Users\SUNNY\workspace\XYZPro\fda\lib\site-packages\django\views\generic\base.py", line 69, in view
    return self.dispatch(request, *args, **kwargs)
  File "C:\Users\SUNNY\workspace\XYZPro\fda\lib\site-packages\django\views\generic\base.py", line 89, in dispatch
    return handler(request, *args, **kwargs)
  File "C:\Users\SUNNY\workspace\XYZPro\fda\lib\site-packages\django\views\generic\list.py", line 142, in get
    self.object_list = self.get_queryset()
  File "C:\Users\SUNNY\workspace\XYZPro\XYZFDA\account\views.py", line 168, in get_queryset
    Q(name__startswith=query) or Q(date__gte=query2, date__lt=query5))
  File "C:\Users\SUNNY\workspace\XYZPro\fda\lib\site-packages\django\db\models\manager.py", line 82, in manager_method
    return getattr(self.get_queryset(), name)(*args, **kwargs)
  File "C:\Users\SUNNY\workspace\XYZPro\fda\lib\site-packages\django\db\models\query.py", line 836, in filter
    return self._filter_or_exclude(False, *args, **kwargs)
  File "C:\Users\SUNNY\workspace\XYZPro\fda\lib\site-packages\django\db\models\query.py", line 854, in _filter_or_exclude
    clone.query.add_q(Q(*args, **kwargs))
  File "C:\Users\SUNNY\workspace\XYZPro\fda\lib\site-packages\django\db\models\sql\query.py", line 1253, in add_q
    clause, _ = self._add_q(q_object, self.used_aliases)
  File "C:\Users\SUNNY\workspace\XYZPro\fda\lib\site-packages\django\db\models\sql\query.py", line 1271, in _add_q
    current_negated, allow_joins, split_subq)
  File "C:\Users\SUNNY\workspace\XYZPro\fda\lib\site-packages\django\db\models\sql\query.py", line 1277, in _add_q
    split_subq=split_subq,
  File "C:\Users\SUNNY\workspace\XYZPro\fda\lib\site-packages\django\db\models\sql\query.py", line 1215, in build_filter
    condition = self.build_lookup(lookups, col, value)
  File "C:\Users\SUNNY\workspace\XYZPro\fda\lib\site-packages\django\db\models\sql\query.py", line 1090, in build_lookup
    raise ValueError("Cannot use None as a query value")
ValueError: Cannot use None as a query value
2019-08-07 18:22:00,029 ERROR MESSAGE: Internal Server Error: /search_result/
Traceback (most recent call last):
  File "C:\Users\SUNNY\workspace\XYZPro\fda\lib\site-packages\django\core\handlers\exception.py", line 35, in inner
    response = get_response(request)
  File "C:\Users\SUNNY\workspace\XYZPro\fda\lib\site-packages\django\core\handlers\base.py", line 128, in _get_response
    response = self.process_exception_by_middleware(e, request)
  File "C:\Users\SUNNY\workspace\XYZPro\fda\lib\site-packages\django\core\handlers\base.py", line 126, in _get_response
    response = wrapped_callback(request, *callback_args, **callback_kwargs)
  File "C:\Users\SUNNY\workspace\XYZPro\fda\lib\site-packages\django\contrib\auth\decorators.py", line 21, in _wrapped_view
    return view_func(request, *args, **kwargs)
  File "C:\Users\SUNNY\workspace\XYZPro\fda\lib\site-packages\django\views\generic\base.py", line 69, in view
    return self.dispatch(request, *args, **kwargs)
  File "C:\Users\SUNNY\workspace\XYZPro\fda\lib\site-packages\django\views\generic\base.py", line 89, in dispatch
    return handler(request, *args, **kwargs)
  File "C:\Users\SUNNY\workspace\XYZPro\fda\lib\site-packages\django\views\generic\list.py", line 142, in get
    self.object_list = self.get_queryset()
  File "C:\Users\SUNNY\workspace\XYZPro\XYZFDA\account\views.py", line 168, in get_queryset
    Q(name__startswith=query) or Q(date__gte=query2, date__lt=query5))
  File "C:\Users\SUNNY\workspace\XYZPro\fda\lib\site-packages\django\db\models\manager.py", line 82, in manager_method
    return getattr(self.get_queryset(), name)(*args, **kwargs)
  File "C:\Users\SUNNY\workspace\XYZPro\fda\lib\site-packages\django\db\models\query.py", line 836, in filter
    return self._filter_or_exclude(False, *args, **kwargs)
  File "C:\Users\SUNNY\workspace\XYZPro\fda\lib\site-packages\django\db\models\query.py", line 854, in _filter_or_exclude
    clone.query.add_q(Q(*args, **kwargs))
  File "C:\Users\SUNNY\workspace\XYZPro\fda\lib\site-packages\django\db\models\sql\query.py", line 1253, in add_q
    clause, _ = self._add_q(q_object, self.used_aliases)
  File "C:\Users\SUNNY\workspace\XYZPro\fda\lib\site-packages\django\db\models\sql\query.py", line 1271, in _add_q
    current_negated, allow_joins, split_subq)
  File "C:\Users\SUNNY\workspace\XYZPro\fda\lib\site-packages\django\db\models\sql\query.py", line 1277, in _add_q
    split_subq=split_subq,
  File "C:\Users\SUNNY\workspace\XYZPro\fda\lib\site-packages\django\db\models\sql\query.py", line 1215, in build_filter
    condition = self.build_lookup(lookups, col, value)
  File "C:\Users\SUNNY\workspace\XYZPro\fda\lib\site-packages\django\db\models\sql\query.py", line 1090, in build_lookup
    raise ValueError("Cannot use None as a query value")
ValueError: Cannot use None as a query value
2019-08-07 18:22:11,340 ERROR MESSAGE: Internal Server Error: /search_result/
Traceback (most recent call last):
  File "C:\Users\SUNNY\workspace\XYZPro\fda\lib\site-packages\django\core\handlers\exception.py", line 35, in inner
    response = get_response(request)
  File "C:\Users\SUNNY\workspace\XYZPro\fda\lib\site-packages\django\core\handlers\base.py", line 128, in _get_response
    response = self.process_exception_by_middleware(e, request)
  File "C:\Users\SUNNY\workspace\XYZPro\fda\lib\site-packages\django\core\handlers\base.py", line 126, in _get_response
    response = wrapped_callback(request, *callback_args, **callback_kwargs)
  File "C:\Users\SUNNY\workspace\XYZPro\fda\lib\site-packages\django\contrib\auth\decorators.py", line 21, in _wrapped_view
    return view_func(request, *args, **kwargs)
  File "C:\Users\SUNNY\workspace\XYZPro\fda\lib\site-packages\django\views\generic\base.py", line 69, in view
    return self.dispatch(request, *args, **kwargs)
  File "C:\Users\SUNNY\workspace\XYZPro\fda\lib\site-packages\django\views\generic\base.py", line 89, in dispatch
    return handler(request, *args, **kwargs)
  File "C:\Users\SUNNY\workspace\XYZPro\fda\lib\site-packages\django\views\generic\list.py", line 142, in get
    self.object_list = self.get_queryset()
  File "C:\Users\SUNNY\workspace\XYZPro\XYZFDA\account\views.py", line 168, in get_queryset
    Q(name__startswith=query) or Q(date__gte=query2, date__lt=query5))
  File "C:\Users\SUNNY\workspace\XYZPro\fda\lib\site-packages\django\db\models\manager.py", line 82, in manager_method
    return getattr(self.get_queryset(), name)(*args, **kwargs)
  File "C:\Users\SUNNY\workspace\XYZPro\fda\lib\site-packages\django\db\models\query.py", line 836, in filter
    return self._filter_or_exclude(False, *args, **kwargs)
  File "C:\Users\SUNNY\workspace\XYZPro\fda\lib\site-packages\django\db\models\query.py", line 854, in _filter_or_exclude
    clone.query.add_q(Q(*args, **kwargs))
  File "C:\Users\SUNNY\workspace\XYZPro\fda\lib\site-packages\django\db\models\sql\query.py", line 1253, in add_q
    clause, _ = self._add_q(q_object, self.used_aliases)
  File "C:\Users\SUNNY\workspace\XYZPro\fda\lib\site-packages\django\db\models\sql\query.py", line 1271, in _add_q
    current_negated, allow_joins, split_subq)
  File "C:\Users\SUNNY\workspace\XYZPro\fda\lib\site-packages\django\db\models\sql\query.py", line 1277, in _add_q
    split_subq=split_subq,
  File "C:\Users\SUNNY\workspace\XYZPro\fda\lib\site-packages\django\db\models\sql\query.py", line 1215, in build_filter
    condition = self.build_lookup(lookups, col, value)
  File "C:\Users\SUNNY\workspace\XYZPro\fda\lib\site-packages\django\db\models\sql\query.py", line 1090, in build_lookup
    raise ValueError("Cannot use None as a query value")
ValueError: Cannot use None as a query value
2019-08-07 18:25:35,160 WARNING MESSAGE: Not Found: /home/#.png
2019-08-07 18:26:02,069 ERROR MESSAGE: Internal Server Error: /search_result/
Traceback (most recent call last):
  File "C:\Users\SUNNY\workspace\XYZPro\fda\lib\site-packages\django\core\handlers\exception.py", line 35, in inner
    response = get_response(request)
  File "C:\Users\SUNNY\workspace\XYZPro\fda\lib\site-packages\django\core\handlers\base.py", line 128, in _get_response
    response = self.process_exception_by_middleware(e, request)
  File "C:\Users\SUNNY\workspace\XYZPro\fda\lib\site-packages\django\core\handlers\base.py", line 126, in _get_response
    response = wrapped_callback(request, *callback_args, **callback_kwargs)
  File "C:\Users\SUNNY\workspace\XYZPro\fda\lib\site-packages\django\contrib\auth\decorators.py", line 21, in _wrapped_view
    return view_func(request, *args, **kwargs)
  File "C:\Users\SUNNY\workspace\XYZPro\fda\lib\site-packages\django\views\generic\base.py", line 69, in view
    return self.dispatch(request, *args, **kwargs)
  File "C:\Users\SUNNY\workspace\XYZPro\fda\lib\site-packages\django\views\generic\base.py", line 89, in dispatch
    return handler(request, *args, **kwargs)
  File "C:\Users\SUNNY\workspace\XYZPro\fda\lib\site-packages\django\views\generic\list.py", line 142, in get
    self.object_list = self.get_queryset()
  File "C:\Users\SUNNY\workspace\XYZPro\XYZFDA\account\views.py", line 168, in get_queryset
    Q(name__startswith=query) or Q(date__gte=query2, date__lt=query5))
  File "C:\Users\SUNNY\workspace\XYZPro\fda\lib\site-packages\django\db\models\manager.py", line 82, in manager_method
    return getattr(self.get_queryset(), name)(*args, **kwargs)
  File "C:\Users\SUNNY\workspace\XYZPro\fda\lib\site-packages\django\db\models\query.py", line 836, in filter
    return self._filter_or_exclude(False, *args, **kwargs)
  File "C:\Users\SUNNY\workspace\XYZPro\fda\lib\site-packages\django\db\models\query.py", line 854, in _filter_or_exclude
    clone.query.add_q(Q(*args, **kwargs))
  File "C:\Users\SUNNY\workspace\XYZPro\fda\lib\site-packages\django\db\models\sql\query.py", line 1253, in add_q
    clause, _ = self._add_q(q_object, self.used_aliases)
  File "C:\Users\SUNNY\workspace\XYZPro\fda\lib\site-packages\django\db\models\sql\query.py", line 1271, in _add_q
    current_negated, allow_joins, split_subq)
  File "C:\Users\SUNNY\workspace\XYZPro\fda\lib\site-packages\django\db\models\sql\query.py", line 1277, in _add_q
    split_subq=split_subq,
  File "C:\Users\SUNNY\workspace\XYZPro\fda\lib\site-packages\django\db\models\sql\query.py", line 1215, in build_filter
    condition = self.build_lookup(lookups, col, value)
  File "C:\Users\SUNNY\workspace\XYZPro\fda\lib\site-packages\django\db\models\sql\query.py", line 1090, in build_lookup
    raise ValueError("Cannot use None as a query value")
ValueError: Cannot use None as a query value
2019-08-07 18:26:33,215 ERROR MESSAGE: Internal Server Error: /search_result/
Traceback (most recent call last):
  File "C:\Users\SUNNY\workspace\XYZPro\fda\lib\site-packages\django\core\handlers\exception.py", line 35, in inner
    response = get_response(request)
  File "C:\Users\SUNNY\workspace\XYZPro\fda\lib\site-packages\django\core\handlers\base.py", line 128, in _get_response
    response = self.process_exception_by_middleware(e, request)
  File "C:\Users\SUNNY\workspace\XYZPro\fda\lib\site-packages\django\core\handlers\base.py", line 126, in _get_response
    response = wrapped_callback(request, *callback_args, **callback_kwargs)
  File "C:\Users\SUNNY\workspace\XYZPro\fda\lib\site-packages\django\contrib\auth\decorators.py", line 21, in _wrapped_view
    return view_func(request, *args, **kwargs)
  File "C:\Users\SUNNY\workspace\XYZPro\fda\lib\site-packages\django\views\generic\base.py", line 69, in view
    return self.dispatch(request, *args, **kwargs)
  File "C:\Users\SUNNY\workspace\XYZPro\fda\lib\site-packages\django\views\generic\base.py", line 89, in dispatch
    return handler(request, *args, **kwargs)
  File "C:\Users\SUNNY\workspace\XYZPro\fda\lib\site-packages\django\views\generic\list.py", line 142, in get
    self.object_list = self.get_queryset()
  File "C:\Users\SUNNY\workspace\XYZPro\XYZFDA\account\views.py", line 168, in get_queryset
    Q(name__startswith=query) or Q(date__gte=query2, date__lt=query5))
  File "C:\Users\SUNNY\workspace\XYZPro\fda\lib\site-packages\django\db\models\manager.py", line 82, in manager_method
    return getattr(self.get_queryset(), name)(*args, **kwargs)
  File "C:\Users\SUNNY\workspace\XYZPro\fda\lib\site-packages\django\db\models\query.py", line 836, in filter
    return self._filter_or_exclude(False, *args, **kwargs)
  File "C:\Users\SUNNY\workspace\XYZPro\fda\lib\site-packages\django\db\models\query.py", line 854, in _filter_or_exclude
    clone.query.add_q(Q(*args, **kwargs))
  File "C:\Users\SUNNY\workspace\XYZPro\fda\lib\site-packages\django\db\models\sql\query.py", line 1253, in add_q
    clause, _ = self._add_q(q_object, self.used_aliases)
  File "C:\Users\SUNNY\workspace\XYZPro\fda\lib\site-packages\django\db\models\sql\query.py", line 1271, in _add_q
    current_negated, allow_joins, split_subq)
  File "C:\Users\SUNNY\workspace\XYZPro\fda\lib\site-packages\django\db\models\sql\query.py", line 1277, in _add_q
    split_subq=split_subq,
  File "C:\Users\SUNNY\workspace\XYZPro\fda\lib\site-packages\django\db\models\sql\query.py", line 1215, in build_filter
    condition = self.build_lookup(lookups, col, value)
  File "C:\Users\SUNNY\workspace\XYZPro\fda\lib\site-packages\django\db\models\sql\query.py", line 1090, in build_lookup
    raise ValueError("Cannot use None as a query value")
ValueError: Cannot use None as a query value
2019-08-07 18:26:59,157 ERROR MESSAGE: Internal Server Error: /search_result/
Traceback (most recent call last):
  File "C:\Users\SUNNY\workspace\XYZPro\fda\lib\site-packages\django\core\handlers\exception.py", line 35, in inner
    response = get_response(request)
  File "C:\Users\SUNNY\workspace\XYZPro\fda\lib\site-packages\django\core\handlers\base.py", line 128, in _get_response
    response = self.process_exception_by_middleware(e, request)
  File "C:\Users\SUNNY\workspace\XYZPro\fda\lib\site-packages\django\core\handlers\base.py", line 126, in _get_response
    response = wrapped_callback(request, *callback_args, **callback_kwargs)
  File "C:\Users\SUNNY\workspace\XYZPro\fda\lib\site-packages\django\contrib\auth\decorators.py", line 21, in _wrapped_view
    return view_func(request, *args, **kwargs)
  File "C:\Users\SUNNY\workspace\XYZPro\fda\lib\site-packages\django\views\generic\base.py", line 69, in view
    return self.dispatch(request, *args, **kwargs)
  File "C:\Users\SUNNY\workspace\XYZPro\fda\lib\site-packages\django\views\generic\base.py", line 89, in dispatch
    return handler(request, *args, **kwargs)
  File "C:\Users\SUNNY\workspace\XYZPro\fda\lib\site-packages\django\views\generic\list.py", line 142, in get
    self.object_list = self.get_queryset()
  File "C:\Users\SUNNY\workspace\XYZPro\XYZFDA\account\views.py", line 168, in get_queryset
    Q(name__startswith=query) or Q(date__gte=query2, date__lt=query5))
  File "C:\Users\SUNNY\workspace\XYZPro\fda\lib\site-packages\django\db\models\manager.py", line 82, in manager_method
    return getattr(self.get_queryset(), name)(*args, **kwargs)
  File "C:\Users\SUNNY\workspace\XYZPro\fda\lib\site-packages\django\db\models\query.py", line 836, in filter
    return self._filter_or_exclude(False, *args, **kwargs)
  File "C:\Users\SUNNY\workspace\XYZPro\fda\lib\site-packages\django\db\models\query.py", line 854, in _filter_or_exclude
    clone.query.add_q(Q(*args, **kwargs))
  File "C:\Users\SUNNY\workspace\XYZPro\fda\lib\site-packages\django\db\models\sql\query.py", line 1253, in add_q
    clause, _ = self._add_q(q_object, self.used_aliases)
  File "C:\Users\SUNNY\workspace\XYZPro\fda\lib\site-packages\django\db\models\sql\query.py", line 1271, in _add_q
    current_negated, allow_joins, split_subq)
  File "C:\Users\SUNNY\workspace\XYZPro\fda\lib\site-packages\django\db\models\sql\query.py", line 1277, in _add_q
    split_subq=split_subq,
  File "C:\Users\SUNNY\workspace\XYZPro\fda\lib\site-packages\django\db\models\sql\query.py", line 1215, in build_filter
    condition = self.build_lookup(lookups, col, value)
  File "C:\Users\SUNNY\workspace\XYZPro\fda\lib\site-packages\django\db\models\sql\query.py", line 1090, in build_lookup
    raise ValueError("Cannot use None as a query value")
ValueError: Cannot use None as a query value
2019-08-07 18:31:33,614 ERROR MESSAGE: Internal Server Error: /search_result/
Traceback (most recent call last):
  File "C:\Users\SUNNY\workspace\XYZPro\fda\lib\site-packages\django\core\handlers\exception.py", line 35, in inner
    response = get_response(request)
  File "C:\Users\SUNNY\workspace\XYZPro\fda\lib\site-packages\django\core\handlers\base.py", line 128, in _get_response
    response = self.process_exception_by_middleware(e, request)
  File "C:\Users\SUNNY\workspace\XYZPro\fda\lib\site-packages\django\core\handlers\base.py", line 126, in _get_response
    response = wrapped_callback(request, *callback_args, **callback_kwargs)
  File "C:\Users\SUNNY\workspace\XYZPro\fda\lib\site-packages\django\contrib\auth\decorators.py", line 21, in _wrapped_view
    return view_func(request, *args, **kwargs)
  File "C:\Users\SUNNY\workspace\XYZPro\fda\lib\site-packages\django\views\generic\base.py", line 69, in view
    return self.dispatch(request, *args, **kwargs)
  File "C:\Users\SUNNY\workspace\XYZPro\fda\lib\site-packages\django\views\generic\base.py", line 89, in dispatch
    return handler(request, *args, **kwargs)
  File "C:\Users\SUNNY\workspace\XYZPro\fda\lib\site-packages\django\views\generic\list.py", line 142, in get
    self.object_list = self.get_queryset()
  File "C:\Users\SUNNY\workspace\XYZPro\XYZFDA\account\views.py", line 167, in get_queryset
    qu =Visitor_perma.objects.filter(Q(name__startswith=query))
  File "C:\Users\SUNNY\workspace\XYZPro\fda\lib\site-packages\django\db\models\manager.py", line 82, in manager_method
    return getattr(self.get_queryset(), name)(*args, **kwargs)
  File "C:\Users\SUNNY\workspace\XYZPro\fda\lib\site-packages\django\db\models\query.py", line 836, in filter
    return self._filter_or_exclude(False, *args, **kwargs)
  File "C:\Users\SUNNY\workspace\XYZPro\fda\lib\site-packages\django\db\models\query.py", line 854, in _filter_or_exclude
    clone.query.add_q(Q(*args, **kwargs))
  File "C:\Users\SUNNY\workspace\XYZPro\fda\lib\site-packages\django\db\models\sql\query.py", line 1253, in add_q
    clause, _ = self._add_q(q_object, self.used_aliases)
  File "C:\Users\SUNNY\workspace\XYZPro\fda\lib\site-packages\django\db\models\sql\query.py", line 1271, in _add_q
    current_negated, allow_joins, split_subq)
  File "C:\Users\SUNNY\workspace\XYZPro\fda\lib\site-packages\django\db\models\sql\query.py", line 1277, in _add_q
    split_subq=split_subq,
  File "C:\Users\SUNNY\workspace\XYZPro\fda\lib\site-packages\django\db\models\sql\query.py", line 1215, in build_filter
    condition = self.build_lookup(lookups, col, value)
  File "C:\Users\SUNNY\workspace\XYZPro\fda\lib\site-packages\django\db\models\sql\query.py", line 1090, in build_lookup
    raise ValueError("Cannot use None as a query value")
ValueError: Cannot use None as a query value
2019-08-07 18:31:48,805 ERROR MESSAGE: Internal Server Error: /search_result/
Traceback (most recent call last):
  File "C:\Users\SUNNY\workspace\XYZPro\fda\lib\site-packages\django\core\handlers\exception.py", line 35, in inner
    response = get_response(request)
  File "C:\Users\SUNNY\workspace\XYZPro\fda\lib\site-packages\django\core\handlers\base.py", line 128, in _get_response
    response = self.process_exception_by_middleware(e, request)
  File "C:\Users\SUNNY\workspace\XYZPro\fda\lib\site-packages\django\core\handlers\base.py", line 126, in _get_response
    response = wrapped_callback(request, *callback_args, **callback_kwargs)
  File "C:\Users\SUNNY\workspace\XYZPro\fda\lib\site-packages\django\contrib\auth\decorators.py", line 21, in _wrapped_view
    return view_func(request, *args, **kwargs)
  File "C:\Users\SUNNY\workspace\XYZPro\fda\lib\site-packages\django\views\generic\base.py", line 69, in view
    return self.dispatch(request, *args, **kwargs)
  File "C:\Users\SUNNY\workspace\XYZPro\fda\lib\site-packages\django\views\generic\base.py", line 89, in dispatch
    return handler(request, *args, **kwargs)
  File "C:\Users\SUNNY\workspace\XYZPro\fda\lib\site-packages\django\views\generic\list.py", line 142, in get
    self.object_list = self.get_queryset()
  File "C:\Users\SUNNY\workspace\XYZPro\XYZFDA\account\views.py", line 167, in get_queryset
    qu =Visitor_perma.objects.filter(Q(name__startswith=query))
  File "C:\Users\SUNNY\workspace\XYZPro\fda\lib\site-packages\django\db\models\manager.py", line 82, in manager_method
    return getattr(self.get_queryset(), name)(*args, **kwargs)
  File "C:\Users\SUNNY\workspace\XYZPro\fda\lib\site-packages\django\db\models\query.py", line 836, in filter
    return self._filter_or_exclude(False, *args, **kwargs)
  File "C:\Users\SUNNY\workspace\XYZPro\fda\lib\site-packages\django\db\models\query.py", line 854, in _filter_or_exclude
    clone.query.add_q(Q(*args, **kwargs))
  File "C:\Users\SUNNY\workspace\XYZPro\fda\lib\site-packages\django\db\models\sql\query.py", line 1253, in add_q
    clause, _ = self._add_q(q_object, self.used_aliases)
  File "C:\Users\SUNNY\workspace\XYZPro\fda\lib\site-packages\django\db\models\sql\query.py", line 1271, in _add_q
    current_negated, allow_joins, split_subq)
  File "C:\Users\SUNNY\workspace\XYZPro\fda\lib\site-packages\django\db\models\sql\query.py", line 1277, in _add_q
    split_subq=split_subq,
  File "C:\Users\SUNNY\workspace\XYZPro\fda\lib\site-packages\django\db\models\sql\query.py", line 1215, in build_filter
    condition = self.build_lookup(lookups, col, value)
  File "C:\Users\SUNNY\workspace\XYZPro\fda\lib\site-packages\django\db\models\sql\query.py", line 1090, in build_lookup
    raise ValueError("Cannot use None as a query value")
ValueError: Cannot use None as a query value
2019-08-07 18:34:56,978 ERROR MESSAGE: Internal Server Error: /search_result/
Traceback (most recent call last):
  File "C:\Users\SUNNY\workspace\XYZPro\fda\lib\site-packages\django\core\handlers\exception.py", line 35, in inner
    response = get_response(request)
  File "C:\Users\SUNNY\workspace\XYZPro\fda\lib\site-packages\django\core\handlers\base.py", line 128, in _get_response
    response = self.process_exception_by_middleware(e, request)
  File "C:\Users\SUNNY\workspace\XYZPro\fda\lib\site-packages\django\core\handlers\base.py", line 126, in _get_response
    response = wrapped_callback(request, *callback_args, **callback_kwargs)
  File "C:\Users\SUNNY\workspace\XYZPro\fda\lib\site-packages\django\contrib\auth\decorators.py", line 21, in _wrapped_view
    return view_func(request, *args, **kwargs)
  File "C:\Users\SUNNY\workspace\XYZPro\fda\lib\site-packages\django\views\generic\base.py", line 69, in view
    return self.dispatch(request, *args, **kwargs)
  File "C:\Users\SUNNY\workspace\XYZPro\fda\lib\site-packages\django\views\generic\base.py", line 89, in dispatch
    return handler(request, *args, **kwargs)
  File "C:\Users\SUNNY\workspace\XYZPro\fda\lib\site-packages\django\views\generic\list.py", line 142, in get
    self.object_list = self.get_queryset()
  File "C:\Users\SUNNY\workspace\XYZPro\XYZFDA\account\views.py", line 168, in get_queryset
    qu =Visitor_perma.objects.filter(Q(name__icontains=query))
  File "C:\Users\SUNNY\workspace\XYZPro\fda\lib\site-packages\django\db\models\manager.py", line 82, in manager_method
    return getattr(self.get_queryset(), name)(*args, **kwargs)
  File "C:\Users\SUNNY\workspace\XYZPro\fda\lib\site-packages\django\db\models\query.py", line 836, in filter
    return self._filter_or_exclude(False, *args, **kwargs)
  File "C:\Users\SUNNY\workspace\XYZPro\fda\lib\site-packages\django\db\models\query.py", line 854, in _filter_or_exclude
    clone.query.add_q(Q(*args, **kwargs))
  File "C:\Users\SUNNY\workspace\XYZPro\fda\lib\site-packages\django\db\models\sql\query.py", line 1253, in add_q
    clause, _ = self._add_q(q_object, self.used_aliases)
  File "C:\Users\SUNNY\workspace\XYZPro\fda\lib\site-packages\django\db\models\sql\query.py", line 1271, in _add_q
    current_negated, allow_joins, split_subq)
  File "C:\Users\SUNNY\workspace\XYZPro\fda\lib\site-packages\django\db\models\sql\query.py", line 1277, in _add_q
    split_subq=split_subq,
  File "C:\Users\SUNNY\workspace\XYZPro\fda\lib\site-packages\django\db\models\sql\query.py", line 1215, in build_filter
    condition = self.build_lookup(lookups, col, value)
  File "C:\Users\SUNNY\workspace\XYZPro\fda\lib\site-packages\django\db\models\sql\query.py", line 1090, in build_lookup
    raise ValueError("Cannot use None as a query value")
ValueError: Cannot use None as a query value
2019-08-07 18:38:59,508 ERROR MESSAGE: Internal Server Error: /accounts/signup/admin/
Traceback (most recent call last):
  File "C:\Users\SUNNY\workspace\XYZPro\fda\lib\site-packages\django\core\handlers\exception.py", line 35, in inner
    response = get_response(request)
  File "C:\Users\SUNNY\workspace\XYZPro\fda\lib\site-packages\django\core\handlers\base.py", line 128, in _get_response
    response = self.process_exception_by_middleware(e, request)
  File "C:\Users\SUNNY\workspace\XYZPro\fda\lib\site-packages\django\core\handlers\base.py", line 126, in _get_response
    response = wrapped_callback(request, *callback_args, **callback_kwargs)
  File "C:\Users\SUNNY\workspace\XYZPro\fda\lib\site-packages\django\views\generic\base.py", line 69, in view
    return self.dispatch(request, *args, **kwargs)
  File "C:\Users\SUNNY\workspace\XYZPro\fda\lib\site-packages\django\views\generic\base.py", line 89, in dispatch
    return handler(request, *args, **kwargs)
  File "C:\Users\SUNNY\workspace\XYZPro\fda\lib\site-packages\django\views\generic\edit.py", line 172, in post
    return super().post(request, *args, **kwargs)
  File "C:\Users\SUNNY\workspace\XYZPro\fda\lib\site-packages\django\views\generic\edit.py", line 142, in post
    return self.form_valid(form)
  File "C:\Users\SUNNY\workspace\XYZPro\XYZFDA\account\views.py", line 61, in form_valid
    return redirect('account_app:dashboard')
  File "C:\Users\SUNNY\workspace\XYZPro\fda\lib\site-packages\django\shortcuts.py", line 58, in redirect
    return redirect_class(resolve_url(to, *args, **kwargs))
  File "C:\Users\SUNNY\workspace\XYZPro\fda\lib\site-packages\django\shortcuts.py", line 149, in resolve_url
    return reverse(to, args=args, kwargs=kwargs)
  File "C:\Users\SUNNY\workspace\XYZPro\fda\lib\site-packages\django\urls\base.py", line 88, in reverse
    return iri_to_uri(resolver._reverse_with_prefix(view, prefix, *args, **kwargs))
  File "C:\Users\SUNNY\workspace\XYZPro\fda\lib\site-packages\django\urls\resolvers.py", line 632, in _reverse_with_prefix
    raise NoReverseMatch(msg)
django.urls.exceptions.NoReverseMatch: Reverse for 'dashboard' not found. 'dashboard' is not a valid view function or pattern name.
2019-08-07 18:42:40,246 WARNING MESSAGE: Not Found: /home/#.png
2019-08-07 18:44:02,009 WARNING MESSAGE: Not Found: /home/#.png
2019-08-07 18:44:05,660 WARNING MESSAGE: Not Found: /password_reset/bootstrap.css
2019-08-07 18:48:39,471 ERROR MESSAGE: Internal Server Error: /password_reset/
Traceback (most recent call last):
  File "C:\Users\SUNNY\workspace\XYZPro\fda\lib\site-packages\django\core\handlers\exception.py", line 35, in inner
    response = get_response(request)
  File "C:\Users\SUNNY\workspace\XYZPro\fda\lib\site-packages\django\core\handlers\base.py", line 128, in _get_response
    response = self.process_exception_by_middleware(e, request)
  File "C:\Users\SUNNY\workspace\XYZPro\fda\lib\site-packages\django\core\handlers\base.py", line 126, in _get_response
    response = wrapped_callback(request, *callback_args, **callback_kwargs)
  File "C:\Users\SUNNY\workspace\XYZPro\fda\lib\site-packages\django\views\generic\base.py", line 69, in view
    return self.dispatch(request, *args, **kwargs)
  File "C:\Users\SUNNY\workspace\XYZPro\fda\lib\site-packages\django\utils\decorators.py", line 62, in _wrapper
    return bound_func(*args, **kwargs)
  File "C:\Users\SUNNY\workspace\XYZPro\fda\lib\site-packages\django\utils\decorators.py", line 142, in _wrapped_view
    response = view_func(request, *args, **kwargs)
  File "C:\Users\SUNNY\workspace\XYZPro\fda\lib\site-packages\django\utils\decorators.py", line 58, in bound_func
    return func.__get__(self, type(self))(*args2, **kwargs2)
  File "C:\Users\SUNNY\workspace\XYZPro\fda\lib\site-packages\django\contrib\auth\views.py", line 406, in dispatch
    return super().dispatch(*args, **kwargs)
  File "C:\Users\SUNNY\workspace\XYZPro\fda\lib\site-packages\django\views\generic\base.py", line 89, in dispatch
    return handler(request, *args, **kwargs)
  File "C:\Users\SUNNY\workspace\XYZPro\fda\lib\site-packages\django\views\generic\edit.py", line 142, in post
    return self.form_valid(form)
  File "C:\Users\SUNNY\workspace\XYZPro\fda\lib\site-packages\django\contrib\auth\views.py", line 419, in form_valid
    form.save(**opts)
  File "C:\Users\SUNNY\workspace\XYZPro\fda\lib\site-packages\django\contrib\auth\forms.py", line 297, in save
    email, html_email_template_name=html_email_template_name,
  File "C:\Users\SUNNY\workspace\XYZPro\fda\lib\site-packages\django\contrib\auth\forms.py", line 251, in send_mail
    email_message.send()
  File "C:\Users\SUNNY\workspace\XYZPro\fda\lib\site-packages\django\core\mail\message.py", line 294, in send
    return self.get_conXYZtion(fail_silently).send_messages([self])
  File "C:\Users\SUNNY\workspace\XYZPro\fda\lib\site-packages\django\core\mail\backends\smtp.py", line 103, in send_messages
    new_conn_created = self.open()
  File "C:\Users\SUNNY\workspace\XYZPro\fda\lib\site-packages\django\core\mail\backends\smtp.py", line 70, in open
    self.conXYZtion.login(self.username, self.password)
  File "c:\users\sunny\appdata\local\programs\python\python37\Lib\smtplib.py", line 730, in login
    raise last_exception
  File "c:\users\sunny\appdata\local\programs\python\python37\Lib\smtplib.py", line 721, in login
    initial_response_ok=initial_response_ok)
  File "c:\users\sunny\appdata\local\programs\python\python37\Lib\smtplib.py", line 642, in auth
    raise SMTPAuthenticationError(code, resp)
smtplib.SMTPAuthenticationError: (535, b'5.7.8 Username and Password not accepted. Learn more at\n5.7.8  https://support.google.com/mail/?p=BadCredentials s5sm75243830pfm.97 - gsmtp')
2019-08-07 18:50:15,597 ERROR MESSAGE: Internal Server Error: /password_reset/
Traceback (most recent call last):
  File "C:\Users\SUNNY\workspace\XYZPro\fda\lib\site-packages\django\core\handlers\exception.py", line 35, in inner
    response = get_response(request)
  File "C:\Users\SUNNY\workspace\XYZPro\fda\lib\site-packages\django\core\handlers\base.py", line 128, in _get_response
    response = self.process_exception_by_middleware(e, request)
  File "C:\Users\SUNNY\workspace\XYZPro\fda\lib\site-packages\django\core\handlers\base.py", line 126, in _get_response
    response = wrapped_callback(request, *callback_args, **callback_kwargs)
  File "C:\Users\SUNNY\workspace\XYZPro\fda\lib\site-packages\django\views\generic\base.py", line 69, in view
    return self.dispatch(request, *args, **kwargs)
  File "C:\Users\SUNNY\workspace\XYZPro\fda\lib\site-packages\django\utils\decorators.py", line 62, in _wrapper
    return bound_func(*args, **kwargs)
  File "C:\Users\SUNNY\workspace\XYZPro\fda\lib\site-packages\django\utils\decorators.py", line 142, in _wrapped_view
    response = view_func(request, *args, **kwargs)
  File "C:\Users\SUNNY\workspace\XYZPro\fda\lib\site-packages\django\utils\decorators.py", line 58, in bound_func
    return func.__get__(self, type(self))(*args2, **kwargs2)
  File "C:\Users\SUNNY\workspace\XYZPro\fda\lib\site-packages\django\contrib\auth\views.py", line 406, in dispatch
    return super().dispatch(*args, **kwargs)
  File "C:\Users\SUNNY\workspace\XYZPro\fda\lib\site-packages\django\views\generic\base.py", line 89, in dispatch
    return handler(request, *args, **kwargs)
  File "C:\Users\SUNNY\workspace\XYZPro\fda\lib\site-packages\django\views\generic\edit.py", line 142, in post
    return self.form_valid(form)
  File "C:\Users\SUNNY\workspace\XYZPro\fda\lib\site-packages\django\contrib\auth\views.py", line 419, in form_valid
    form.save(**opts)
  File "C:\Users\SUNNY\workspace\XYZPro\fda\lib\site-packages\django\contrib\auth\forms.py", line 297, in save
    email, html_email_template_name=html_email_template_name,
  File "C:\Users\SUNNY\workspace\XYZPro\fda\lib\site-packages\django\contrib\auth\forms.py", line 251, in send_mail
    email_message.send()
  File "C:\Users\SUNNY\workspace\XYZPro\fda\lib\site-packages\django\core\mail\message.py", line 294, in send
    return self.get_conXYZtion(fail_silently).send_messages([self])
  File "C:\Users\SUNNY\workspace\XYZPro\fda\lib\site-packages\django\core\mail\backends\smtp.py", line 103, in send_messages
    new_conn_created = self.open()
  File "C:\Users\SUNNY\workspace\XYZPro\fda\lib\site-packages\django\core\mail\backends\smtp.py", line 63, in open
    self.conXYZtion = self.conXYZtion_class(self.host, self.port, **conXYZtion_params)
  File "c:\users\sunny\appdata\local\programs\python\python37\Lib\smtplib.py", line 251, in __init__
    (code, msg) = self.conXYZt(host, port)
  File "c:\users\sunny\appdata\local\programs\python\python37\Lib\smtplib.py", line 336, in conXYZt
    self.sock = self._get_socket(host, port, self.timeout)
  File "c:\users\sunny\appdata\local\programs\python\python37\Lib\smtplib.py", line 307, in _get_socket
    self.source_address)
  File "c:\users\sunny\appdata\local\programs\python\python37\Lib\socket.py", line 707, in create_conXYZtion
    for res in getaddrinfo(host, port, 0, SOCK_STREAM):
  File "c:\users\sunny\appdata\local\programs\python\python37\Lib\socket.py", line 748, in getaddrinfo
    for res in _socket.getaddrinfo(host, port, family, type, proto, flags):
socket.gaierror: [Errno 11001] getaddrinfo failed
2019-08-07 18:56:15,467 WARNING MESSAGE: Not Found: /password_reset/bootstrap.css
2019-08-07 19:08:55,332 WARNING MESSAGE: Not Found: /home/#.png
2019-08-07 19:11:47,084 WARNING MESSAGE: Not Found: /home/#.png
2019-08-07 19:15:02,533 ERROR MESSAGE: Internal Server Error: /display
Traceback (most recent call last):
  File "C:\Users\SUNNY\workspace\XYZPro\fda\lib\site-packages\django\core\handlers\exception.py", line 35, in inner
    response = get_response(request)
  File "C:\Users\SUNNY\workspace\XYZPro\fda\lib\site-packages\django\core\handlers\base.py", line 128, in _get_response
    response = self.process_exception_by_middleware(e, request)
  File "C:\Users\SUNNY\workspace\XYZPro\fda\lib\site-packages\django\core\handlers\base.py", line 126, in _get_response
    response = wrapped_callback(request, *callback_args, **callback_kwargs)
  File "C:\Users\SUNNY\workspace\XYZPro\fda\lib\site-packages\django\contrib\auth\decorators.py", line 21, in _wrapped_view
    return view_func(request, *args, **kwargs)
  File "C:\Users\SUNNY\workspace\XYZPro\XYZFDA\account\views.py", line 182, in display
    visit= form.save(commit=False)
  File "C:\Users\SUNNY\workspace\XYZPro\fda\lib\site-packages\django\forms\models.py", line 451, in save
    'created' if self.instance._state.adding else 'changed',
ValueError: The Temp could not be changed because the data didn't validate.
2019-08-07 19:19:16,529 ERROR MESSAGE: Internal Server Error: /display
Traceback (most recent call last):
  File "C:\Users\SUNNY\workspace\XYZPro\fda\lib\site-packages\django\core\handlers\exception.py", line 35, in inner
    response = get_response(request)
  File "C:\Users\SUNNY\workspace\XYZPro\fda\lib\site-packages\django\core\handlers\base.py", line 128, in _get_response
    response = self.process_exception_by_middleware(e, request)
  File "C:\Users\SUNNY\workspace\XYZPro\fda\lib\site-packages\django\core\handlers\base.py", line 126, in _get_response
    response = wrapped_callback(request, *callback_args, **callback_kwargs)
  File "C:\Users\SUNNY\workspace\XYZPro\fda\lib\site-packages\django\contrib\auth\decorators.py", line 21, in _wrapped_view
    return view_func(request, *args, **kwargs)
  File "C:\Users\SUNNY\workspace\XYZPro\XYZFDA\account\views.py", line 184, in display
    visit= form.save(commit=False)
  File "C:\Users\SUNNY\workspace\XYZPro\fda\lib\site-packages\django\forms\models.py", line 451, in save
    'created' if self.instance._state.adding else 'changed',
ValueError: The Temp could not be changed because the data didn't validate.
2019-08-07 19:30:23,785 WARNING MESSAGE: Not Found: /home/#.png
2019-08-07 19:35:43,893 ERROR MESSAGE: Internal Server Error: /search_result/
Traceback (most recent call last):
  File "C:\Users\SUNNY\workspace\XYZPro\fda\lib\site-packages\django\core\handlers\exception.py", line 35, in inner
    response = get_response(request)
  File "C:\Users\SUNNY\workspace\XYZPro\fda\lib\site-packages\django\core\handlers\base.py", line 128, in _get_response
    response = self.process_exception_by_middleware(e, request)
  File "C:\Users\SUNNY\workspace\XYZPro\fda\lib\site-packages\django\core\handlers\base.py", line 126, in _get_response
    response = wrapped_callback(request, *callback_args, **callback_kwargs)
  File "C:\Users\SUNNY\workspace\XYZPro\fda\lib\site-packages\django\contrib\auth\decorators.py", line 21, in _wrapped_view
    return view_func(request, *args, **kwargs)
  File "C:\Users\SUNNY\workspace\XYZPro\fda\lib\site-packages\django\views\generic\base.py", line 69, in view
    return self.dispatch(request, *args, **kwargs)
  File "C:\Users\SUNNY\workspace\XYZPro\fda\lib\site-packages\django\views\generic\base.py", line 89, in dispatch
    return handler(request, *args, **kwargs)
  File "C:\Users\SUNNY\workspace\XYZPro\fda\lib\site-packages\django\views\generic\list.py", line 142, in get
    self.object_list = self.get_queryset()
  File "C:\Users\SUNNY\workspace\XYZPro\XYZFDA\account\views.py", line 168, in get_queryset
    qu =Visitor_perma.objects.filter(Q(name__startswith=query))
  File "C:\Users\SUNNY\workspace\XYZPro\fda\lib\site-packages\django\db\models\manager.py", line 82, in manager_method
    return getattr(self.get_queryset(), name)(*args, **kwargs)
  File "C:\Users\SUNNY\workspace\XYZPro\fda\lib\site-packages\django\db\models\query.py", line 836, in filter
    return self._filter_or_exclude(False, *args, **kwargs)
  File "C:\Users\SUNNY\workspace\XYZPro\fda\lib\site-packages\django\db\models\query.py", line 854, in _filter_or_exclude
    clone.query.add_q(Q(*args, **kwargs))
  File "C:\Users\SUNNY\workspace\XYZPro\fda\lib\site-packages\django\db\models\sql\query.py", line 1253, in add_q
    clause, _ = self._add_q(q_object, self.used_aliases)
  File "C:\Users\SUNNY\workspace\XYZPro\fda\lib\site-packages\django\db\models\sql\query.py", line 1271, in _add_q
    current_negated, allow_joins, split_subq)
  File "C:\Users\SUNNY\workspace\XYZPro\fda\lib\site-packages\django\db\models\sql\query.py", line 1277, in _add_q
    split_subq=split_subq,
  File "C:\Users\SUNNY\workspace\XYZPro\fda\lib\site-packages\django\db\models\sql\query.py", line 1215, in build_filter
    condition = self.build_lookup(lookups, col, value)
  File "C:\Users\SUNNY\workspace\XYZPro\fda\lib\site-packages\django\db\models\sql\query.py", line 1090, in build_lookup
    raise ValueError("Cannot use None as a query value")
ValueError: Cannot use None as a query value
2019-08-07 20:00:40,189 WARNING MESSAGE: Not Found: /home/#.png
2019-08-07 20:10:30,023 WARNING MESSAGE: Not Found: /home/#.png
2019-08-07 20:10:51,921 WARNING MESSAGE: Not Found: /home/#.png
2019-08-07 20:16:37,516 WARNING MESSAGE: Not Found: /home/#.png
2019-08-07 20:16:42,073 WARNING MESSAGE: Not Found: /home/#.png
2019-08-07 20:16:50,821 WARNING MESSAGE: Not Found: /home/#.png
2019-08-07 20:17:02,102 WARNING MESSAGE: Not Found: /home/#.png
2019-08-07 20:17:19,342 WARNING MESSAGE: Not Found: /home/#.png
2019-08-07 20:17:25,198 WARNING MESSAGE: Not Found: /home/#.png
2019-08-07 20:24:42,985 WARNING MESSAGE: Not Found: /home/#.png
2019-08-07 20:28:24,955 WARNING MESSAGE: Not Found: /home/#.png
2019-08-07 20:28:25,552 WARNING MESSAGE: Not Found: /favicon.ico
2019-08-07 20:28:51,387 WARNING MESSAGE: Not Found: /home/#.png
2019-08-07 20:28:53,279 WARNING MESSAGE: Not Found: /favicon.ico
2019-08-07 20:33:55,189 WARNING MESSAGE: Not Found: /home/#.png
2019-08-07 20:36:23,905 WARNING MESSAGE: Not Found: /home/#.png
2019-08-07 20:39:23,548 WARNING MESSAGE: Not Found: /home/#.png
2019-08-07 20:39:43,246 WARNING MESSAGE: Not Found: /search_ans/style.css
2019-08-07 20:39:43,256 WARNING MESSAGE: Not Found: /search_ans/temp.png
2019-08-07 20:43:13,877 WARNING MESSAGE: Not Found: /search_ans/style.css
2019-08-07 20:43:13,890 WARNING MESSAGE: Not Found: /search_ans/temp.png
2019-08-07 20:44:32,128 WARNING MESSAGE: Not Found: /search_ans/style.css
2019-08-07 20:44:32,144 WARNING MESSAGE: Not Found: /search_ans/temp.png
2019-08-07 20:45:36,473 WARNING MESSAGE: Not Found: /search_ans/style.css
2019-08-07 20:45:36,491 WARNING MESSAGE: Not Found: /search_ans/temp.png
2019-08-07 20:48:06,877 WARNING MESSAGE: Not Found: /search_ans/style.css
2019-08-07 20:48:06,900 WARNING MESSAGE: Not Found: /search_ans/temp.png
2019-08-07 20:51:42,396 WARNING MESSAGE: Not Found: /search_ans/style.css
2019-08-07 20:51:42,415 WARNING MESSAGE: Not Found: /search_ans/temp.png
2019-08-07 20:53:25,471 WARNING MESSAGE: Not Found: /search_ans/style.css
2019-08-07 20:53:25,488 WARNING MESSAGE: Not Found: /search_ans/temp.png
2019-08-07 20:56:30,081 WARNING MESSAGE: Not Found: /search_ans/style.css
2019-08-07 20:56:30,099 WARNING MESSAGE: Not Found: /search_ans/temp.png
2019-08-07 20:57:41,893 ERROR MESSAGE: Internal Server Error: /search_ans/
Traceback (most recent call last):
  File "C:\Users\SUNNY\workspace\XYZPro\fda\lib\site-packages\django\core\handlers\exception.py", line 35, in inner
    response = get_response(request)
  File "C:\Users\SUNNY\workspace\XYZPro\fda\lib\site-packages\django\core\handlers\base.py", line 128, in _get_response
    response = self.process_exception_by_middleware(e, request)
  File "C:\Users\SUNNY\workspace\XYZPro\fda\lib\site-packages\django\core\handlers\base.py", line 126, in _get_response
    response = wrapped_callback(request, *callback_args, **callback_kwargs)
  File "C:\Users\SUNNY\workspace\XYZPro\fda\lib\site-packages\django\contrib\auth\decorators.py", line 21, in _wrapped_view
    return view_func(request, *args, **kwargs)
  File "C:\Users\SUNNY\workspace\XYZPro\XYZFDA\account\views.py", line 224, in get_queryset2
    instance = Visitor_perma.objects.get(phone=query)
  File "C:\Users\SUNNY\workspace\XYZPro\fda\lib\site-packages\django\db\models\manager.py", line 82, in manager_method
    return getattr(self.get_queryset(), name)(*args, **kwargs)
  File "C:\Users\SUNNY\workspace\XYZPro\fda\lib\site-packages\django\db\models\query.py", line 407, in get
    (self.model._meta.object_name, num)
account.models.MultipleObjectsReturned: get() returned more than one Visitor_perma -- it returned 2!
2019-08-07 20:58:25,043 ERROR MESSAGE: Internal Server Error: /search_ans/
Traceback (most recent call last):
  File "C:\Users\SUNNY\workspace\XYZPro\fda\lib\site-packages\django\core\handlers\exception.py", line 35, in inner
    response = get_response(request)
  File "C:\Users\SUNNY\workspace\XYZPro\fda\lib\site-packages\django\core\handlers\base.py", line 128, in _get_response
    response = self.process_exception_by_middleware(e, request)
  File "C:\Users\SUNNY\workspace\XYZPro\fda\lib\site-packages\django\core\handlers\base.py", line 126, in _get_response
    response = wrapped_callback(request, *callback_args, **callback_kwargs)
  File "C:\Users\SUNNY\workspace\XYZPro\fda\lib\site-packages\django\contrib\auth\decorators.py", line 21, in _wrapped_view
    return view_func(request, *args, **kwargs)
  File "C:\Users\SUNNY\workspace\XYZPro\XYZFDA\account\views.py", line 224, in get_queryset2
    instance = Visitor_perma.objects.get(phone=query).first()
  File "C:\Users\SUNNY\workspace\XYZPro\fda\lib\site-packages\django\db\models\manager.py", line 82, in manager_method
    return getattr(self.get_queryset(), name)(*args, **kwargs)
  File "C:\Users\SUNNY\workspace\XYZPro\fda\lib\site-packages\django\db\models\query.py", line 407, in get
    (self.model._meta.object_name, num)
account.models.MultipleObjectsReturned: get() returned more than one Visitor_perma -- it returned 2!
2019-08-07 20:58:29,323 WARNING MESSAGE: Not Found: /search_ans/style.css
2019-08-07 20:58:31,546 ERROR MESSAGE: Internal Server Error: /search_ans/
Traceback (most recent call last):
  File "C:\Users\SUNNY\workspace\XYZPro\fda\lib\site-packages\django\core\handlers\exception.py", line 35, in inner
    response = get_response(request)
  File "C:\Users\SUNNY\workspace\XYZPro\fda\lib\site-packages\django\core\handlers\base.py", line 128, in _get_response
    response = self.process_exception_by_middleware(e, request)
  File "C:\Users\SUNNY\workspace\XYZPro\fda\lib\site-packages\django\core\handlers\base.py", line 126, in _get_response
    response = wrapped_callback(request, *callback_args, **callback_kwargs)
  File "C:\Users\SUNNY\workspace\XYZPro\fda\lib\site-packages\django\contrib\auth\decorators.py", line 21, in _wrapped_view
    return view_func(request, *args, **kwargs)
  File "C:\Users\SUNNY\workspace\XYZPro\XYZFDA\account\views.py", line 224, in get_queryset2
    instance = Visitor_perma.objects.get(phone=query).first()
  File "C:\Users\SUNNY\workspace\XYZPro\fda\lib\site-packages\django\db\models\manager.py", line 82, in manager_method
    return getattr(self.get_queryset(), name)(*args, **kwargs)
  File "C:\Users\SUNNY\workspace\XYZPro\fda\lib\site-packages\django\db\models\query.py", line 407, in get
    (self.model._meta.object_name, num)
account.models.MultipleObjectsReturned: get() returned more than one Visitor_perma -- it returned 2!
2019-08-07 21:01:25,854 WARNING MESSAGE: Not Found: /search_ans/style.css
2019-08-07 21:01:32,077 ERROR MESSAGE: Internal Server Error: /search_ans/
Traceback (most recent call last):
  File "C:\Users\SUNNY\workspace\XYZPro\fda\lib\site-packages\django\core\handlers\exception.py", line 35, in inner
    response = get_response(request)
  File "C:\Users\SUNNY\workspace\XYZPro\fda\lib\site-packages\django\core\handlers\base.py", line 128, in _get_response
    response = self.process_exception_by_middleware(e, request)
  File "C:\Users\SUNNY\workspace\XYZPro\fda\lib\site-packages\django\core\handlers\base.py", line 126, in _get_response
    response = wrapped_callback(request, *callback_args, **callback_kwargs)
  File "C:\Users\SUNNY\workspace\XYZPro\fda\lib\site-packages\django\contrib\auth\decorators.py", line 21, in _wrapped_view
    return view_func(request, *args, **kwargs)
  File "C:\Users\SUNNY\workspace\XYZPro\XYZFDA\account\views.py", line 224, in get_queryset2
    instance = Visitor_perma.objects.get(phone=query).last()
  File "C:\Users\SUNNY\workspace\XYZPro\fda\lib\site-packages\django\db\models\manager.py", line 82, in manager_method
    return getattr(self.get_queryset(), name)(*args, **kwargs)
  File "C:\Users\SUNNY\workspace\XYZPro\fda\lib\site-packages\django\db\models\query.py", line 407, in get
    (self.model._meta.object_name, num)
account.models.MultipleObjectsReturned: get() returned more than one Visitor_perma -- it returned 2!
2019-08-07 21:02:36,068 WARNING MESSAGE: Not Found: /search_ans/style.css
2019-08-07 21:02:36,084 WARNING MESSAGE: Not Found: /search_ans/temp.png
2019-08-07 21:03:27,970 WARNING MESSAGE: Not Found: /search_ans/style.css
2019-08-07 21:03:27,983 WARNING MESSAGE: Not Found: /search_ans/temp.png
2019-08-07 21:07:43,417 WARNING MESSAGE: Not Found: /home/#.png
2019-08-07 21:08:53,553 WARNING MESSAGE: Not Found: /home/#.png
2019-08-07 21:10:45,028 WARNING MESSAGE: Not Found: /search_ans/style.css
2019-08-07 21:10:45,047 WARNING MESSAGE: Not Found: /search_ans/temp.png
2019-08-07 21:22:18,773 WARNING MESSAGE: Not Found: /home/#.png
2019-08-07 21:22:20,518 WARNING MESSAGE: Not Found: /home/#.png
2019-08-07 21:22:49,842 WARNING MESSAGE: Not Found: /home/#.png
2019-08-07 21:23:51,563 WARNING MESSAGE: Not Found: /search_ans/style.css
2019-08-07 21:23:51,573 WARNING MESSAGE: Not Found: /search_ans/temp.png
2019-08-07 21:23:58,460 WARNING MESSAGE: Not Found: /home/#.png
2019-08-07 21:24:55,075 WARNING MESSAGE: Not Found: /home/#.png
2019-08-07 21:24:59,750 WARNING MESSAGE: Not Found: /password_reset/bootstrap.css
2019-08-07 21:28:59,434 WARNING MESSAGE: Not Found: /password_reset/bootstrap.css
2019-08-07 21:29:45,437 WARNING MESSAGE: Not Found: /password_reset/bootstrap.css
2019-08-07 17:19:58,489 WARNING MESSAGE: Not Found: /
2019-08-07 17:19:59,472 WARNING MESSAGE: Not Found: /favicon.ico
2019-08-07 17:20:03,707 WARNING MESSAGE: Not Found: /favicon.ico
2019-08-31 17:51:03,348 WARNING MESSAGE: Not Found: /
2019-08-31 17:51:07,774 WARNING MESSAGE: Not Found: /home/#.png
2019-09-01 05:01:40,564 WARNING MESSAGE: Not Found: /
2019-09-01 05:22:15,626 WARNING MESSAGE: Not Found: /
2019-09-01 05:22:22,071 WARNING MESSAGE: Not Found: /home/#.png
2019-09-01 05:22:23,016 WARNING MESSAGE: Not Found: /favicon.ico
2019-09-01 05:43:58,285 WARNING MESSAGE: Not Found: /home/#.png
2019-09-01 05:48:36,179 WARNING MESSAGE: Not Found: /home/#.png
2019-09-01 05:48:40,091 WARNING MESSAGE: Not Found: /home/#.png
2019-09-01 05:50:08,468 WARNING MESSAGE: Not Found: /home/#.png
2019-09-01 05:50:57,264 WARNING MESSAGE: Not Found: /home/#.png
2019-09-01 05:51:05,976 WARNING MESSAGE: Not Found: /home/#.png
2019-09-01 05:51:14,838 WARNING MESSAGE: Not Found: /home/#.png
2019-09-01 05:59:37,505 WARNING MESSAGE: Not Found: /
2019-09-01 06:00:30,868 ERROR MESSAGE: Internal Server Error: /dashboard/
Traceback (most recent call last):
  File "/home/rathivikal/.local/lib/python3.6/site-packages/django/core/handlers/exception.py", line 35, in inner
    response = get_response(request)
  File "/home/rathivikal/.local/lib/python3.6/site-packages/django/core/handlers/base.py", line 139, in _get_response
    "returned None instead." % (callback.__module__, view_name)
ValueError: The view account.views.dashboard didn't return an HttpResponse object. It returned None instead.
2019-09-01 06:12:55,244 WARNING MESSAGE: Not Found: /search_ans/style.css
2019-09-01 06:12:55,461 WARNING MESSAGE: Not Found: /search_ans/temp.png
2019-09-01 06:14:08,586 WARNING MESSAGE: Not Found: /search_ans/style.css
2019-09-01 06:15:12,173 WARNING MESSAGE: Not Found: /search_ans/style.css
2019-09-01 06:15:12,689 WARNING MESSAGE: Not Found: /search_ans/temp.png
2019-09-01 06:16:34,027 WARNING MESSAGE: Not Found: /search_ans/style.css
2019-09-01 06:16:34,471 WARNING MESSAGE: Not Found: /search_ans/temp.png
2019-09-01 06:16:37,236 WARNING MESSAGE: Not Found: /search_ans/style.css
2019-09-01 06:16:37,425 WARNING MESSAGE: Not Found: /search_ans/temp.png
2019-09-01 06:17:21,302 WARNING MESSAGE: Not Found: /search_ans/style.css
2019-09-01 06:17:21,733 WARNING MESSAGE: Not Found: /search_ans/temp.png
2019-09-01 06:21:23,483 WARNING MESSAGE: Not Found: /
2019-09-01 06:30:44,685 WARNING MESSAGE: Not Found: /
2019-09-01 06:33:18,635 WARNING MESSAGE: Not Found: /password_reset/bootstrap.css
2019-09-01 06:48:33,516 WARNING MESSAGE: Not Found: /password_reset/bootstrap.css
2019-09-01 06:58:19,529 ERROR MESSAGE: Internal Server Error: /dashboard/
Traceback (most recent call last):
  File "/home/rathivikal/.local/lib/python3.6/site-packages/django/core/handlers/exception.py", line 35, in inner
    response = get_response(request)
  File "/home/rathivikal/.local/lib/python3.6/site-packages/django/core/handlers/base.py", line 128, in _get_response
    response = self.process_exception_by_middleware(e, request)
  File "/home/rathivikal/.local/lib/python3.6/site-packages/django/core/handlers/base.py", line 126, in _get_response
    response = wrapped_callback(request, *callback_args, **callback_kwargs)
  File "/home/rathivikal/.local/lib/python3.6/site-packages/django/contrib/auth/decorators.py", line 21, in _wrapped_view
    return view_func(request, *args, **kwargs)
  File "/home/rathivikal/Desktop/Vaibhav_San_Group/NECFDA-final/account/views.py", line 124, in dashboard
    return render(request, 'admin-dashboard.html')
  File "/home/rathivikal/.local/lib/python3.6/site-packages/django/shortcuts.py", line 36, in render
    content = loader.render_to_string(template_name, context, request, using=using)
  File "/home/rathivikal/.local/lib/python3.6/site-packages/django/template/loader.py", line 62, in render_to_string
    return template.render(context, request)
  File "/home/rathivikal/.local/lib/python3.6/site-packages/django/template/backends/django.py", line 61, in render
    return self.template.render(context)
  File "/home/rathivikal/.local/lib/python3.6/site-packages/django/template/base.py", line 175, in render
    return self._render(context)
  File "/home/rathivikal/.local/lib/python3.6/site-packages/django/template/base.py", line 167, in _render
    return self.nodelist.render(context)
  File "/home/rathivikal/.local/lib/python3.6/site-packages/django/template/base.py", line 943, in render
    bit = node.render_annotated(context)
  File "/home/rathivikal/.local/lib/python3.6/site-packages/django/template/base.py", line 910, in render_annotated
    return self.render(context)
  File "/home/rathivikal/.local/lib/python3.6/site-packages/django/template/defaulttags.py", line 447, in render
    url = reverse(view_name, args=args, kwargs=kwargs, current_app=current_app)
  File "/home/rathivikal/.local/lib/python3.6/site-packages/django/urls/base.py", line 88, in reverse
    return iri_to_uri(resolver._reverse_with_prefix(view, prefix, *args, **kwargs))
  File "/home/rathivikal/.local/lib/python3.6/site-packages/django/urls/resolvers.py", line 632, in _reverse_with_prefix
    raise NoReverseMatch(msg)
django.urls.exceptions.NoReverseMatch: Reverse for 'download' not found. 'download' is not a valid view function or pattern name.
2019-09-01 06:58:57,397 ERROR MESSAGE: Internal Server Error: /dashboard/
Traceback (most recent call last):
  File "/home/rathivikal/.local/lib/python3.6/site-packages/django/core/handlers/exception.py", line 35, in inner
    response = get_response(request)
  File "/home/rathivikal/.local/lib/python3.6/site-packages/django/core/handlers/base.py", line 128, in _get_response
    response = self.process_exception_by_middleware(e, request)
  File "/home/rathivikal/.local/lib/python3.6/site-packages/django/core/handlers/base.py", line 126, in _get_response
    response = wrapped_callback(request, *callback_args, **callback_kwargs)
  File "/home/rathivikal/.local/lib/python3.6/site-packages/django/contrib/auth/decorators.py", line 21, in _wrapped_view
    return view_func(request, *args, **kwargs)
  File "/home/rathivikal/Desktop/Vaibhav_San_Group/NECFDA-final/account/views.py", line 124, in dashboard
    return render(request, 'admin-dashboard.html')
  File "/home/rathivikal/.local/lib/python3.6/site-packages/django/shortcuts.py", line 36, in render
    content = loader.render_to_string(template_name, context, request, using=using)
  File "/home/rathivikal/.local/lib/python3.6/site-packages/django/template/loader.py", line 62, in render_to_string
    return template.render(context, request)
  File "/home/rathivikal/.local/lib/python3.6/site-packages/django/template/backends/django.py", line 61, in render
    return self.template.render(context)
  File "/home/rathivikal/.local/lib/python3.6/site-packages/django/template/base.py", line 175, in render
    return self._render(context)
  File "/home/rathivikal/.local/lib/python3.6/site-packages/django/template/base.py", line 167, in _render
    return self.nodelist.render(context)
  File "/home/rathivikal/.local/lib/python3.6/site-packages/django/template/base.py", line 943, in render
    bit = node.render_annotated(context)
  File "/home/rathivikal/.local/lib/python3.6/site-packages/django/template/base.py", line 910, in render_annotated
    return self.render(context)
  File "/home/rathivikal/.local/lib/python3.6/site-packages/django/template/defaulttags.py", line 447, in render
    url = reverse(view_name, args=args, kwargs=kwargs, current_app=current_app)
  File "/home/rathivikal/.local/lib/python3.6/site-packages/django/urls/base.py", line 88, in reverse
    return iri_to_uri(resolver._reverse_with_prefix(view, prefix, *args, **kwargs))
  File "/home/rathivikal/.local/lib/python3.6/site-packages/django/urls/resolvers.py", line 632, in _reverse_with_prefix
    raise NoReverseMatch(msg)
django.urls.exceptions.NoReverseMatch: Reverse for '' not found. '' is not a valid view function or pattern name.
2019-09-01 06:59:10,025 ERROR MESSAGE: Internal Server Error: /dashboard/
Traceback (most recent call last):
  File "/home/rathivikal/.local/lib/python3.6/site-packages/django/core/handlers/exception.py", line 35, in inner
    response = get_response(request)
  File "/home/rathivikal/.local/lib/python3.6/site-packages/django/core/handlers/base.py", line 128, in _get_response
    response = self.process_exception_by_middleware(e, request)
  File "/home/rathivikal/.local/lib/python3.6/site-packages/django/core/handlers/base.py", line 126, in _get_response
    response = wrapped_callback(request, *callback_args, **callback_kwargs)
  File "/home/rathivikal/.local/lib/python3.6/site-packages/django/contrib/auth/decorators.py", line 21, in _wrapped_view
    return view_func(request, *args, **kwargs)
  File "/home/rathivikal/Desktop/Vaibhav_San_Group/NECFDA-final/account/views.py", line 124, in dashboard
    return render(request, 'admin-dashboard.html')
  File "/home/rathivikal/.local/lib/python3.6/site-packages/django/shortcuts.py", line 36, in render
    content = loader.render_to_string(template_name, context, request, using=using)
  File "/home/rathivikal/.local/lib/python3.6/site-packages/django/template/loader.py", line 62, in render_to_string
    return template.render(context, request)
  File "/home/rathivikal/.local/lib/python3.6/site-packages/django/template/backends/django.py", line 61, in render
    return self.template.render(context)
  File "/home/rathivikal/.local/lib/python3.6/site-packages/django/template/base.py", line 175, in render
    return self._render(context)
  File "/home/rathivikal/.local/lib/python3.6/site-packages/django/template/base.py", line 167, in _render
    return self.nodelist.render(context)
  File "/home/rathivikal/.local/lib/python3.6/site-packages/django/template/base.py", line 943, in render
    bit = node.render_annotated(context)
  File "/home/rathivikal/.local/lib/python3.6/site-packages/django/template/base.py", line 910, in render_annotated
    return self.render(context)
  File "/home/rathivikal/.local/lib/python3.6/site-packages/django/template/defaulttags.py", line 447, in render
    url = reverse(view_name, args=args, kwargs=kwargs, current_app=current_app)
  File "/home/rathivikal/.local/lib/python3.6/site-packages/django/urls/base.py", line 88, in reverse
    return iri_to_uri(resolver._reverse_with_prefix(view, prefix, *args, **kwargs))
  File "/home/rathivikal/.local/lib/python3.6/site-packages/django/urls/resolvers.py", line 632, in _reverse_with_prefix
    raise NoReverseMatch(msg)
django.urls.exceptions.NoReverseMatch: Reverse for '' not found. '' is not a valid view function or pattern name.
2019-09-01 07:00:44,476 ERROR MESSAGE: Internal Server Error: /dashboard/
Traceback (most recent call last):
  File "/home/rathivikal/.local/lib/python3.6/site-packages/django/core/handlers/exception.py", line 35, in inner
    response = get_response(request)
  File "/home/rathivikal/.local/lib/python3.6/site-packages/django/core/handlers/base.py", line 128, in _get_response
    response = self.process_exception_by_middleware(e, request)
  File "/home/rathivikal/.local/lib/python3.6/site-packages/django/core/handlers/base.py", line 126, in _get_response
    response = wrapped_callback(request, *callback_args, **callback_kwargs)
  File "/home/rathivikal/.local/lib/python3.6/site-packages/django/contrib/auth/decorators.py", line 21, in _wrapped_view
    return view_func(request, *args, **kwargs)
  File "/home/rathivikal/Desktop/Vaibhav_San_Group/NECFDA-final/account/views.py", line 124, in dashboard
    return render(request, 'admin-dashboard.html')
  File "/home/rathivikal/.local/lib/python3.6/site-packages/django/shortcuts.py", line 36, in render
    content = loader.render_to_string(template_name, context, request, using=using)
  File "/home/rathivikal/.local/lib/python3.6/site-packages/django/template/loader.py", line 62, in render_to_string
    return template.render(context, request)
  File "/home/rathivikal/.local/lib/python3.6/site-packages/django/template/backends/django.py", line 61, in render
    return self.template.render(context)
  File "/home/rathivikal/.local/lib/python3.6/site-packages/django/template/base.py", line 175, in render
    return self._render(context)
  File "/home/rathivikal/.local/lib/python3.6/site-packages/django/template/base.py", line 167, in _render
    return self.nodelist.render(context)
  File "/home/rathivikal/.local/lib/python3.6/site-packages/django/template/base.py", line 943, in render
    bit = node.render_annotated(context)
  File "/home/rathivikal/.local/lib/python3.6/site-packages/django/template/base.py", line 910, in render_annotated
    return self.render(context)
  File "/home/rathivikal/.local/lib/python3.6/site-packages/django/template/defaulttags.py", line 447, in render
    url = reverse(view_name, args=args, kwargs=kwargs, current_app=current_app)
  File "/home/rathivikal/.local/lib/python3.6/site-packages/django/urls/base.py", line 88, in reverse
    return iri_to_uri(resolver._reverse_with_prefix(view, prefix, *args, **kwargs))
  File "/home/rathivikal/.local/lib/python3.6/site-packages/django/urls/resolvers.py", line 632, in _reverse_with_prefix
    raise NoReverseMatch(msg)
django.urls.exceptions.NoReverseMatch: Reverse for 'download' not found. 'download' is not a valid view function or pattern name.
2019-09-01 07:24:04,443 WARNING MESSAGE: Not Found: /password_reset/bootstrap.css
2019-09-01 07:26:45,579 WARNING MESSAGE: Not Found: /password_reset/bootstrap.css
2019-09-01 08:26:47,780 ERROR MESSAGE: Internal Server Error: /dashboard/
Traceback (most recent call last):
  File "/home/rathivikal/.local/lib/python3.6/site-packages/django/core/handlers/exception.py", line 35, in inner
    response = get_response(request)
  File "/home/rathivikal/.local/lib/python3.6/site-packages/django/core/handlers/base.py", line 128, in _get_response
    response = self.process_exception_by_middleware(e, request)
  File "/home/rathivikal/.local/lib/python3.6/site-packages/django/core/handlers/base.py", line 126, in _get_response
    response = wrapped_callback(request, *callback_args, **callback_kwargs)
  File "/home/rathivikal/.local/lib/python3.6/site-packages/django/contrib/auth/decorators.py", line 21, in _wrapped_view
    return view_func(request, *args, **kwargs)
  File "/home/rathivikal/Desktop/Vaibhav_San_Group/NECFDA-final/account/views.py", line 124, in dashboard
    return render(request, 'admin-dashboard.html')
  File "/home/rathivikal/.local/lib/python3.6/site-packages/django/shortcuts.py", line 36, in render
    content = loader.render_to_string(template_name, context, request, using=using)
  File "/home/rathivikal/.local/lib/python3.6/site-packages/django/template/loader.py", line 62, in render_to_string
    return template.render(context, request)
  File "/home/rathivikal/.local/lib/python3.6/site-packages/django/template/backends/django.py", line 61, in render
    return self.template.render(context)
  File "/home/rathivikal/.local/lib/python3.6/site-packages/django/template/base.py", line 175, in render
    return self._render(context)
  File "/home/rathivikal/.local/lib/python3.6/site-packages/django/template/base.py", line 167, in _render
    return self.nodelist.render(context)
  File "/home/rathivikal/.local/lib/python3.6/site-packages/django/template/base.py", line 943, in render
    bit = node.render_annotated(context)
  File "/home/rathivikal/.local/lib/python3.6/site-packages/django/template/base.py", line 910, in render_annotated
    return self.render(context)
  File "/home/rathivikal/.local/lib/python3.6/site-packages/django/template/defaulttags.py", line 447, in render
    url = reverse(view_name, args=args, kwargs=kwargs, current_app=current_app)
  File "/home/rathivikal/.local/lib/python3.6/site-packages/django/urls/base.py", line 88, in reverse
    return iri_to_uri(resolver._reverse_with_prefix(view, prefix, *args, **kwargs))
  File "/home/rathivikal/.local/lib/python3.6/site-packages/django/urls/resolvers.py", line 632, in _reverse_with_prefix
    raise NoReverseMatch(msg)
django.urls.exceptions.NoReverseMatch: Reverse for 'password' not found. 'password' is not a valid view function or pattern name.
2019-09-01 08:41:03,026 WARNING MESSAGE: Not Found: /password_reset/bootstrap.css
2019-09-01 09:31:51,380 WARNING MESSAGE: Not Found: /
2019-09-01 09:32:02,799 WARNING MESSAGE: Not Found: /password_reset/bootstrap.css
2019-09-01 10:04:46,731 WARNING MESSAGE: Not Found: /password_reset/bootstrap.css
2019-09-01 10:20:38,442 WARNING MESSAGE: Not Found: /
2019-09-01 10:20:53,123 WARNING MESSAGE: Not Found: /password_reset/bootstrap.css
2019-09-01 10:37:09,039 WARNING MESSAGE: Not Found: /password_reset/bootstrap.css
2019-09-01 10:57:49,799 WARNING MESSAGE: Not Found: /
2019-09-01 10:58:00,811 WARNING MESSAGE: Not Found: /password_reset/bootstrap.css
2019-09-01 11:03:26,492 WARNING MESSAGE: Not Found: /
2019-09-01 11:03:55,190 WARNING MESSAGE: Not Found: /password_reset/bootstrap.css
2019-09-01 11:06:45,759 WARNING MESSAGE: Not Found: /accounts/password_reset
2019-09-01 11:07:07,378 WARNING MESSAGE: Not Found: /accounts/password_change
2019-09-01 11:07:21,064 WARNING MESSAGE: Not Found: /accounts/login/
2019-09-01 11:08:52,336 WARNING MESSAGE: Not Found: /accounts/password_reset/
2019-09-01 11:09:00,479 WARNING MESSAGE: Not Found: /password_reset/bootstrap.css
2019-09-01 11:11:43,390 WARNING MESSAGE: Not Found: /accounts/reset/MQ/50n-794b1459497cbe0ed399/
2019-09-01 11:12:01,517 WARNING MESSAGE: Not Found: /accounts/password_reset/done/
2019-09-01 11:12:13,575 WARNING MESSAGE: Not Found: /password_reset/bootstrap.css
2019-09-01 11:14:36,773 WARNING MESSAGE: Not Found: /password_reset/bootstrap.css
2019-09-01 11:14:45,051 WARNING MESSAGE: Not Found: /password_reset/bootstrap.css
2019-09-01 11:29:52,991 WARNING MESSAGE: Not Found: /password_reset/bootstrap.css
2019-09-01 11:33:50,778 WARNING MESSAGE: Not Found: /password_reset/bootstrap.css
2019-09-01 12:00:30,750 WARNING MESSAGE: Not Found: /
2019-09-01 12:00:31,536 WARNING MESSAGE: Not Found: /favicon.ico
2019-09-01 12:00:49,438 WARNING MESSAGE: Not Found: /user_list/<int:id>
2019-09-01 12:02:10,197 ERROR MESSAGE: Internal Server Error: /user/
Traceback (most recent call last):
  File "/home/rathivikal/.local/lib/python3.6/site-packages/django/core/handlers/exception.py", line 35, in inner
    response = get_response(request)
  File "/home/rathivikal/.local/lib/python3.6/site-packages/django/core/handlers/base.py", line 128, in _get_response
    response = self.process_exception_by_middleware(e, request)
  File "/home/rathivikal/.local/lib/python3.6/site-packages/django/core/handlers/base.py", line 126, in _get_response
    response = wrapped_callback(request, *callback_args, **callback_kwargs)
  File "/home/rathivikal/.local/lib/python3.6/site-packages/django/views/decorators/csrf.py", line 54, in wrapped_view
    return view_func(*args, **kwargs)
  File "/home/rathivikal/.local/lib/python3.6/site-packages/django/views/generic/base.py", line 69, in view
    return self.dispatch(request, *args, **kwargs)
  File "/home/rathivikal/.local/lib/python3.6/site-packages/rest_framework/views.py", line 499, in dispatch
    self.response = self.finalize_response(request, response, *args, **kwargs)
  File "/home/rathivikal/.local/lib/python3.6/site-packages/rest_framework/views.py", line 414, in finalize_response
    % type(response)
AssertionError: Expected a `Response`, `HttpResponse` or `HttpStreamingResponse` to be returned from the view, but received a `<class 'NoneType'>`
2019-09-01 12:24:55,745 WARNING MESSAGE: Not Found: /user/2
2019-09-01 14:17:08,273 WARNING MESSAGE: Not Found: /
2019-09-01 14:22:10,373 WARNING MESSAGE: Not Found: /
2019-09-01 14:22:11,082 WARNING MESSAGE: Not Found: /favicon.ico
2019-09-01 14:44:19,515 WARNING MESSAGE: Not Found: /
2019-09-01 14:47:39,096 WARNING MESSAGE: Not Found: /password_reset/bootstrap.css
2019-09-01 15:06:27,061 WARNING MESSAGE: Not Found: /accounts/login/
2019-09-01 16:29:14,247 WARNING MESSAGE: Not Found: /search_ans/style.css
2019-09-01 16:29:14,683 WARNING MESSAGE: Not Found: /search_ans/temp.png
2019-09-01 16:33:56,864 WARNING MESSAGE: Not Found: /search_ans/style.css
2019-09-01 16:33:57,280 WARNING MESSAGE: Not Found: /search_ans/temp.png
2019-09-02 08:01:28,150 WARNING MESSAGE: Not Found: /
2019-09-02 08:01:29,021 WARNING MESSAGE: Not Found: /favicon.ico
2020-04-09 08:30:37,950 WARNING MESSAGE: Not Found: /
2020-04-09 08:30:58,848 WARNING MESSAGE: Not Found: /
2020-04-09 08:31:09,946 WARNING MESSAGE: Not Found: /
2020-04-09 08:31:19,761 WARNING MESSAGE: Not Found: /accounts/login/
2020-04-09 08:31:26,090 WARNING MESSAGE: Not Found: /accounts/login/
2020-04-09 08:35:12,686 WARNING MESSAGE: Not Found: /
2020-04-09 08:35:18,483 WARNING MESSAGE: Not Found: /accounts/login/
2020-04-09 09:00:33,663 WARNING MESSAGE: Not Found: /
2020-04-09 09:01:59,936 WARNING MESSAGE: Not Found: /accounts/login/
2020-04-09 09:02:00,870 WARNING MESSAGE: Not Found: /accounts/login/
2020-04-09 09:04:00,887 WARNING MESSAGE: Not Found: /password_reset/bootstrap.css
2020-04-09 09:14:06,953 WARNING MESSAGE: Not Found: /
2020-04-09 09:14:07,079 WARNING MESSAGE: Not Found: /favicon.ico
2020-04-09 09:15:05,521 WARNING MESSAGE: Not Found: /
2020-04-09 09:15:12,603 WARNING MESSAGE: Not Found: /accounts/login/
2020-04-17 06:17:45,070 WARNING MESSAGE: Not Found: /
2020-04-17 06:17:45,477 WARNING MESSAGE: Not Found: /favicon.ico
2020-04-17 06:21:31,396 WARNING MESSAGE: Not Found: /
2020-04-17 06:31:27,001 WARNING MESSAGE: Not Found: /search_ans/temp.png
2020-04-17 06:31:27,010 WARNING MESSAGE: Not Found: /search_ans/style.css
2020-04-24 06:30:03,660 WARNING MESSAGE: Not Found: /accounts/login/
2020-04-24 06:30:04,030 WARNING MESSAGE: Not Found: /favicon.ico
2020-04-24 07:59:19,567 WARNING MESSAGE: Not Found: /accounts/login/
2020-04-24 07:59:19,761 WARNING MESSAGE: Not Found: /favicon.ico
2020-04-24 07:59:24,794 WARNING MESSAGE: Not Found: /
